Workbook
Name dt: #REF!
Name k_1: #REF!
Name Plocha__m2: #REF!

Sheet Správa TOB
A1: Tabuľka 1: Tepelná ochrana budovy, potreba tepla na vykurovanie a chladenie
A2: Č.r. | B2: ZÁKLADNÉ ÚDAJE O BUDOVE
A3: 1 | C3: Názov budovy: | F3: FaxCopy a.s.
A4: 2 | C4: Ulica, číslo: | F4: Domkárska 15
A5: 3 | C5: Obec: | F5: Bratislava - Ružinov
A6: 4 | C6: Parc. č.:
A7: 5 | C7: Katastrálne územie: | F7: Bratislava
A8: 6 | C8: Účel spracovania energetického certifikátu: | G8: Iný účel
B9: Výpočet potreby tepla na vykurovanie
B10: VSTUPNÉ ÚDAJE
A11: 7 | B11: Budova | D11: Kategória budovy (jeden účel užívania) | I11: 3 - Administratívna budova
A12: 8 | D12: Klimatická lokalita (Mesto pre mesačnú metódu) | I12: Bratislava-letisko
A13: 9 | D13: Zmiešaný účel užívania – kategória 2
A14: 10 | D14: Podiel celkovej podlahovej plochy – kategória 1 | J14: %
A15: 11 | D15: Podiel celkovej podlahovej plochy – kategória 2 | J15: %
A16: 12 | D16: Rok kolaudácie
A17: 13 | D17: Rok poslednej zmeny tepelnej ochrany
A18: 14 | D18: Typ, konšt. systém, stavebná sústava
A19: 15 | D19: Šírka budovy | J19: m
A20: 16 | D20: Dĺžka budovy | J20: m
A21: 17 | D21: Výška budovy | J21: m
A22: 18 | D22: Počet podlaží | I22: 3
A23: 19 | D23: Obostavaný objem | I23: 5273.389 | J23: m³
A24: 20 | D24: Celková podlahová plocha | I24: 1728.98 | J24: m²
A25: 21 | D25: Celková teplovýmenná plocha | I25: =SUM(I34:I36,I38:I40,I42:I44,I47:I49) -> 2956.9 | J25: m²
A26: 22 | D26: Priemerná konštrukčná výška | I26: =IF(I24>0,I23/I24,0) -> 3.05 | J26: m
A27: 23 | D27: Faktor tvaru | I27: =IF(I23>0,I25/I23,0) -> 0.56072101 | J27: 1/m
A28: 24 | B28: Výpočet | D28: Výpočtová metóda | I28: Mesačná
A29: 25 | D29: Počet dennostupňov | I29: =Výpočet_mesacny!Q28 -> 3173.5995 | J29: K.deň
B30: Tepelné straty | C30: Popis/názov obvodovej konštrukcie | G30: Súčiniteľ prechodu tepla konštrukcie Ui (W/(m².K)) | I30: Teplovýmenná | J30: Teplotný
I31: plocha | J31: redukčný
I32: Ai (m²) | J32: faktor b (-)
D33: Obvodový plášť :
A34: 26 | C34: 1 | D34: Obvodová stena | G34: 0.46 | I34: 849.31 | J34: 1
A35: 27 | C35: 2
A36: 28 | C36: 3
D37: Strecha :
A38: 31 | C38: 1 | D38: Strecha | G38: 0.1 | I38: 876 | J38: 1
A39: 32 | C39: 2
A40: 33 | C40: 3
...

Sheet KLIMA_DB
P1: Normatívne letné a zimné výpočtové teploty (STN 73 0540-3)
A2: Key_CityMonth | B2: Lokalita | C2: Mesiac | D2: Te | E2: Sol_Horiz | F2: Sol_South | G2: Sol_North | H2: Sol_East | I2: Sol_West | K2: Mesta Dropdown | M2: Trieda budovy | N2: Cm (J/K.m2) | P2: Mesto | Q2: θe,výpočt,leto [°C] | R2: θe,výpočt,zima [°C]
A3: Nitra_1 | B3: Nitra | C3: 1 | D3: -1.64 | E3: 26 | F3: 42.12 | G3: 13 | H3: 26 | I3: 26 | K3: Nitra | M3: Veľmi ľahká | N3: 80000 | P3: Banska Bystrica | Q3: 29 | R3: -15
A4: Nitra_2 | B4: Nitra | C4: 2 | D4: 0.625 | E4: 49 | F4: 71.54 | G4: 21.07 | H4: 48.51 | I4: 48.51 | K4: Senica | M4: Ľahká | N4: 110000 | P4: Bardejov | Q4: 28 | R4: -15
A5: Nitra_3 | B5: Nitra | C5: 3 | D5: 5.39 | E5: 88 | F5: 110.88 | G5: 44.88 | H5: 84.48 | I5: 84.48 | K5: Topolcany | M5: Stredne ťažká | N5: 165000 | P5: Bratislava-letisko | Q5: 34 | R5: -11
A6: Nitra_4 | B6: Nitra | C6: 4 | D6: 10.755 | E6: 134 | F6: 147.4 | G6: 91.12 | H6: 125.96 | I6: 125.96 | K6: Piestany | M6: Ťažká | N6: 260000 | P6: Dolny Kubin | Q6: 28 | R6: -16
A7: Nitra_5 | B7: Nitra | C7: 5 | D7: 15.655 | E7: 166 | F7: 167.66 | G7: 131.14 | H7: 156.04 | I7: 156.04 | K7: Zilina | M7: Veľmi ťažká | N7: 370000 | P7: Košice-letisko | Q7: 31 | R7: -12
A8: Nitra_6 | B8: Nitra | C8: 6 | D8: 18.6875 | E8: 178 | F8: 172.66 | G8: 145.96 | H8: 165.54 | I8: 165.54 | K8: Dolny Kubin | P8: Liptovský Mikuláš | Q8: 27 | R8: -16
A9: Nitra_7 | B9: Nitra | C9: 7 | D9: 20.3875 | E9: 171 | F9: 167.58 | G9: 138.51 | H9: 159.03 | I9: 159.03 | K9: Banska Bystrica | P9: Nitra | Q9: 32 | R9: -11
A10: Nitra_8 | B10: Nitra | C10: 8 | D10: 19.7875 | E10: 147 | F10: 154.35 | G10: 107.31 | H10: 136.71 | I10: 136.71 | K10: Trebisov | P10: Piestany | Q10: 30 | R10: -11
A11: Nitra_9 | B11: Nitra | C11: 9 | D11: 15.4225 | E11: 111 | F11: 130.98 | G11: 64.38 | H11: 105.45 | I11: 105.45 | K11: Bardejov | P11: Presov | Q11: 30 | R11: -15
A12: Nitra_10 | B12: Nitra | C12: 10 | D12: 10.025 | E12: 64 | F12: 86.4 | G12: 27.52 | H12: 61.44 | I12: 61.44 | K12: Presov | P12: Senica | Q12: 31 | R12: -11
A13: Nitra_11 | B13: Nitra | C13: 11 | D13: 4.4925 | E13: 30 | F13: 45.9 | G13: 13.5 | H13: 29.4 | I13: 29.4 | K13: Bratislava-letisko | P13: Topolcany | Q13: 31 | R13: -11
A14: Nitra_12 | B14: Nitra | C14: 12 | D14: -0.1075 | E14: 20 | F14: 36.2 | G14: 9 | H14: 20 | I14: 20 | K14: Košice-letisko | P14: Trebisov | Q14: 32 | R14: -12
A15: Senica_1 | B15: Senica | C15: 1 | D15: -2.58 | E15: 29 | F15: 46.69 | G15: 15.08 | H15: 29 | I15: 29 | K15: Liptovský Mikuláš | P15: Zilina | Q15: 30 | R15: -15
A16: Senica_2 | B16: Senica | C16: 2 | D16: -0.375 | E16: 52 | F16: 75.4 | G16: 23.4 | H16: 50.96 | I16: 50.96
A17: Senica_3 | B17: Senica | C17: 3 | D17: 4.13 | E17: 95 | F17: 118.75 | G17: 49.4 | H17: 91.2 | I17: 91.2
A18: Senica_4 | B18: Senica | C18: 4 | D18: 9.735 | E18: 138 | F18: 150.42 | G18: 93.84 | H18: 129.72 | I18: 129.72
A19: Senica_5 | B19: Senica | C19: 5 | D19: 14.635 | E19: 172 | F19: 173.72 | G19: 135.88 | H19: 161.68 | I19: 161.68
A20: Senica_6 | B20: Senica | C20: 6 | D20: 17.6375 | E20: 180 | F20: 174.6 | G20: 147.6 | H20: 167.4 | I20: 167.4
A21: Senica_7 | B21: Senica | C21: 7 | D21: 19.2375 | E21: 179 | F21: 175.42 | G21: 144.99 | H21: 166.47 | I21: 166.47
A22: Senica_8 | B22: Senica | C22: 8 | D22: 18.6375 | E22: 155 | F22: 161.2 | G22: 113.15 | H22: 145.7 | I22: 145.7
A23: Senica_9 | B23: Senica | C23: 9 | D23: 14.4325 | E23: 120 | F23: 140.4 | G23: 70.8 | H23: 114 | I23: 114
A24: Senica_10 | B24: Senica | C24: 10 | D24: 9.225 | E24: 73 | F24: 97.09 | G24: 32.85 | H24: 70.08 | I24: 70.08
A25: Senica_11 | B25: Senica | C25: 11 | D25: 3.8225 | E25: 34 | F25: 51.68 | G25: 15.98 | H25: 32.98 | I25: 32.98
A26: Senica_12 | B26: Senica | C26: 12 | D26: -0.7775 | E26: 30 | F26: 52.8 | G26: 14.4 | H26: 29.7 | I26: 29.7
A27: Topolcany_1 | B27: Topolcany | C27: 1 | D27: -2.568 | E27: 26 | F27: 41.86 | G27: 13.52 | H27: 26 | I27: 26
... A158: Liptovský Mikuláš_12 | B158: Liptovský Mikuláš | C158: 12 | D158: -2.4605 | E158: 20 | F158: 35.2 | G158: 9.6 | H158: 19.8 | I158: 19.8

Sheet Výpočet_mesacny
A1: MESAČNÝ VÝPOČET POTREBY TEPLA NA VYKUROVANIE
A2: Metóda: STN EN ISO 13790 - Mesačná metóda (Vykurovacie obdobie)
A5: VSTUPNÉ HODNOTY (VYKUROVANIE):
A6: Ap - Celková podlahová plocha [m²] | D6: ='Správa TOB'!I24 -> 1728.98
A7: V - Obostavaný objem budovy [m³] | D7: ='Správa TOB'!I23 -> 5273.389
A8: θi,adj - Upravená vnútorná teplota [°C] | D8: ='Správa TOB'!I99 -> 18.4 | G8: Tau (časová konštanta) [h]: | H8: =IF(D9>0, D11/(D9*3600), 0) -> 34.228057
A9: H - Celková merná tepelná strata [W/K] | D9: ='Správa TOB'!I112 -> 2315.2035 | G9: Numerický parameter a: | H9: =1 + H8/15 -> 3.2818705
A10: q - Výkon vnútorného zdroja [W/m²] | D10: ='Správa TOB'!I68 -> 6
A11: Cm - Vnútorná tepelná kapacita [J/K] | D11: =IF(ISNUMBER('Správa TOB'!I101),'Správa TOB'!I101*D6,165000*D6) -> 285281700
A15: Mesiac | B15: Dni | C15: θe [°C] | D15: Q_loss [kWh] | E15: Qi [kWh] | F15: Qs [kWh] | G15: Q_gain [kWh] | H15: γ [-] | I15: η [-] | J15: Q_H,nd [kWh] | K15: Vykurovanie?
A16: Jan | B16: 31 | C16: =VLOOKUP('Správa TOB'!$I$12 & "_" & Z16, KLIMA_DB!$A$3:$I$250, 4, FALSE) -> -1.632 | D16: =IF(C16<D$8, D$9*(D$8-C16)*B16*24/1000, 0) -> 34505.348 | E16: =IF(C16<D$8, D$10*D$6*B16*24/1000, 0) -> 7718.1667 | F16: =IF(C16<D$8, (VLOOKUP('Správa TOB'!$I$12 & "_" & Z16, KLIMA_DB!$A$3:$I$250, 6, FALSE))*$O$30 + (VLOOKUP('Správa TOB'!$I$12 & "_" & Z16, KLIMA_DB!$A$3:$I$250, 7, FALSE))*$O$31 + (((VLOOKUP('Správa TOB'!$I$12 & "_" & Z16, KLIMA_DB!$A$3:$I$250, 8, FALSE)+VLOOKUP('Správa TOB'!$I$12 & "_" & Z16, KLIMA_DB!$A$3:$I$250, 9, FALSE))/2))*$O$32 + (((VLOOKUP('Správa TOB'!$I$12 & "_" & Z16, KLIMA_DB!$A$3:$I$250, 6, FALSE)+VLOOKUP('Správa TOB'!$I$12 & "_" & Z16, KLIMA_DB!$A$3:$I$250, 8, FALSE))/2))*$O$33 + (((VLOOKUP('Správa TOB'!$I$12 & "_" & Z16, KLIMA_DB!$A$3:$I$250, 7, FALSE)+VLOOKUP('Správa TOB'!$I$12 & "_" & Z16, KLIMA_DB!$A$3:$I$250, 8, FALSE))/2))*$O$34 + (VLOOKUP('Správa TOB'!$I$12 & "_" & Z16, KLIMA_DB!$A$3:$I$250, 5, FALSE))*$O$35, 0) -> 2094.2542 | G16: =E16+F16 -> 9812.4209 | H16: =IF(D16>0, G16/D16, 0) -> 0.28437391 | I16: =IF(D16=0, 0, IF(H16<=0, 1, IF(ABS(H16-1)<0.001, ($H$9)/($H$9+1), (1-POWER(H16,$H$9))/(1-POWER(H16,$H$9+1))))) -> 0.98840101 | J16: =MAX(0, D16 - I16*G16) -> 24806.742 | K16: =IF(C16<D$8, "ÁNO", "nie") -> ÁNO | Z16: 1
A17: Feb | B17: 28 | C17: =VLOOKUP('Správa TOB'!$I$12 & "_" & Z17, KLIMA_DB!$A$3:$I$250, 4, FALSE) -> 0.635 | D17: =IF(C17<D$8, D$9*(D$8-C17)*B17*24/1000, 0) -> 27639.084 | E17: =IF(C17<D$8, D$10*D$6*B17*24/1000, 0) -> 6971.2474 | F17: =IF(C17<D$8, (VLOOKUP('Správa TOB'!$I$12 & "_" & Z17, KLIMA_DB!$A$3:$I$250, 6, FALSE))*$O$30 + (VLOOKUP('Správa TOB'!$I$12 & "_" & Z17, KLIMA_DB!$A$3:$I$250, 7, FALSE))*$O$31 + (((VLOOKUP('Správa TOB'!$I$12 & "_" & Z17, KLIMA_DB!$A$3:$I$250, 8, FALSE)+VLOOKUP('Správa TOB'!$I$12 & "_" & Z17, KLIMA_DB!$A$3:$I$250, 9, FALSE))/2))*$O$32 + (((VLOOKUP('Správa TOB'!$I$12 & "_" & Z17, KLIMA_DB!$A$3:$I$250, 6, FALSE)+VLOOKUP('Správa TOB'!$I$12 & "_" & Z17, KLIMA_DB!$A$3:$I$250, 8, FALSE))/2))*$O$33 + (((VLOOKUP('Správa TOB'!$I$12 & "_" & Z17, KLIMA_DB!$A$3:$I$250, 7, FALSE)+VLOOKUP('Správa TOB'!$I$12 & "_" & Z17, KLIMA_DB!$A$3:$I$250, 8, FALSE))/2))*$O$34 + (VLOOKUP('Správa TOB'!$I$12 & "_" & Z17, KLIMA_DB!$A$3:$I$250, 5, FALSE))*$O$35, 0) -> 3470.8517 | G17: =E17+F17 -> 10442.099 | H17: =IF(D17>0, G17/D17, 0) -> 0.37780192 | I17: =IF(D17=0, 0, IF(H17<=0, 1, IF(ABS(H17-1)<0.001, ($H$9)/($H$9+1), (1-POWER(H17,$H$9))/(1-POWER(H17,$H$9+1))))) -> 0.97409749 | J17: =MAX(0, D17 - I17*G17) -> 17467.462 | K17: =IF(C17<D$8, "ÁNO", "nie") -> ÁNO | Z17: 2
A18: Mar | B18: 31 | C18: =VLOOKUP('Správa TOB'!$I$12 & "_" & Z18, KLIMA_DB!$A$3:$I$250, 4, FALSE) -> 5.402 | D18: =IF(C18<D$8, D$9*(D$8-C18)*B18*24/1000, 0) -> 22389.203 | E18: =IF(C18<D$8, D$10*D$6*B18*24/1000, 0) -> 7718.1667 | F18: =IF(C18<D$8, (VLOOKUP('Správa TOB'!$I$12 & "_" & Z18, KLIMA_DB!$A$3:$I$250, 6, FALSE))*$O$30 + (VLOOKUP('Správa TOB'!$I$12 & "_" & Z18, KLIMA_DB!$A$3:$I$250, 7, FALSE))*$O$31 + (((VLOOKUP('Správa TOB'!$I$12 & "_" & Z18, KLIMA_DB!$A$3:$I$250, 8, FALSE)+VLOOKUP('Správa TOB'!$I$12 & "_" & Z18, KLIMA_DB!$A$3:$I$250, 9, FALSE))/2))*$O$32 + (((VLOOKUP('Správa TOB'!$I$12 & "_" & Z18, KLIMA_DB!$A$3:$I$250, 6, FALSE)+VLOOKUP('Správa TOB'!$I$12 & "_" & Z18, KLIMA_DB!$A$3:$I$250, 8, FALSE))/2))*$O$33 + (((VLOOKUP('Správa TOB'!$I$12 & "_" & Z18, KLIMA_DB!$A$3:$I$250, 7, FALSE)+VLOOKUP('Správa TOB'!$I$12 & "_" & Z18, KLIMA_DB!$A$3:$I$250, 8, FALSE))/2))*$O$34 + (VLOOKUP('Správa TOB'!$I$12 & "_" & Z18, KLIMA_DB!$A$3:$I$250, 5, FALSE))*$O$35, 0) -> 5738.7312 | G18: =E18+F18 -> 13456.898 | H18: =IF(D18>0, G18/D18, 0) -> 0.60104408 | I18: =IF(D18=0, 0, IF(H18<=0, 1, IF(ABS(H18-1)<0.001, ($H$9)/($H$9+1), (1-POWER(H18,$H$9))/(1-POWER(H18,$H$9+1))))) -> 0.91538849 | J18: =MAX(0, D18 - I18*G18) -> 10070.914 | K18: =IF(C18<D$8, "ÁNO", "nie") -> ÁNO | Z18: 3
A19: Apr | B19: 30 | C19: =VLOOKUP('Správa TOB'!$I$12 & "_" & Z19, KLIMA_DB!$A$3:$I$250, 4, FALSE) -> 10.769 | D19: =IF(C19<D$8, D$9*(D$8-C19)*B19*24/1000, 0) -> 12720.469 | E19: =IF(C19<D$8, D$10*D$6*B19*24/1000, 0) -> 7469.1936 | F19: =IF(C19<D$8, (VLOOKUP('Správa TOB'!$I$12 & "_" & Z19, KLIMA_DB!$A$3:$I$250, 6, FALSE))*$O$30 + (VLOOKUP('Správa TOB'!$I$12 & "_" & Z19, KLIMA_DB!$A$3:$I$250, 7, FALSE))*$O$31 + (((VLOOKUP('Správa TOB'!$I$12 & "_" & Z19, KLIMA_DB!$A$3:$I$250, 8, FALSE)+VLOOKUP('Správa TOB'!$I$12 & "_" & Z19, KLIMA_DB!$A$3:$I$250, 9, FALSE))/2))*$O$32 + (((VLOOKUP('Správa TOB'!$I$12 & "_" & Z19, KLIMA_DB!$A$3:$I$250, 6, FALSE)+VLOOKUP('Správa TOB'!$I$12 & "_" & Z19, KLIMA_DB!$A$3:$I$250, 8, FALSE))/2))*$O$33 + (((VLOOKUP('Správa TOB'!$I$12 & "_" & Z19, KLIMA_DB!$A$3:$I$250, 7, FALSE)+VLOOKUP('Správa TOB'!$I$12 & "_" & Z19, KLIMA_DB!$A$3:$I$250, 8, FALSE))/2))*$O$34 + (VLOOKUP('Správa TOB'!$I$12 & "_" & Z19, KLIMA_DB!$A$3:$I$250, 5, FALSE))*$O$35, 0) -> 8751.4724 | G19: =E19+F19 -> 16220.666 | H19: =IF(D19>0, G19/D19, 0) -> 1.2751626 | I19: =IF(D19=0, 0, IF(H19<=0, 1, IF(ABS(H19-1)<0.001, ($H$9)/($H$9+1), (1-POWER(H19,$H$9))/(1-POWER(H19,$H$9+1))))) -> 0.66639492 | J19: =MAX(0, D19 - I19*G19) -> 1911.0993 | K19: =IF(C19<D$8, "ÁNO", "nie") -> ÁNO | Z19: 4
A20: Máj | B20: 31 | C20: =VLOOKUP('Správa TOB'!$I$12 & "_" & Z20, KLIMA_DB!$A$3:$I$250, 4, FALSE) -> 15.669 | D20: =IF(C20<D$8, D$9*(D$8-C20)*B20*24/1000, 0) -> 4704.1786 | E20: =IF(C20<D$8, D$10*D$6*B20*24/1000, 0) -> 7718.1667 | F20: =IF(C20<D$8, (VLOOKUP('Správa TOB'!$I$12 & "_" & Z20, KLIMA_DB!$A$3:$I$250, 6, FALSE))*$O$30 + (VLOOKUP('Správa TOB'!$I$12 & "_" & Z20, KLIMA_DB!$A$3:$I$250, 7, FALSE))*$O$31 + (((VLOOKUP('Správa TOB'!$I$12 & "_" & Z20, KLIMA_DB!$A$3:$I$250, 8, FALSE)+VLOOKUP('Správa TOB'!$I$12 & "_" & Z20, KLIMA_DB!$A$3:$I$250, 9, FALSE))/2))*$O$32 + (((VLOOKUP('Správa TOB'!$I$12 & "_" & Z20, KLIMA_DB!$A$3:$I$250, 6, FALSE)+VLOOKUP('Správa TOB'!$I$12 & "_" & Z20, KLIMA_DB!$A$3:$I$250, 8, FALSE))/2))*$O$33 + (((VLOOKUP('Správa TOB'!$I$12 & "_" & Z20, KLIMA_DB!$A$3:$I$250, 7, FALSE)+VLOOKUP('Správa TOB'!$I$12 & "_" & Z20, KLIMA_DB!$A$3:$I$250, 8, FALSE))/2))*$O$34 + (VLOOKUP('Správa TOB'!$I$12 & "_" & Z20, KLIMA_DB!$A$3:$I$250, 5, FALSE))*$O$35, 0) -> 10754.553 | G20: =E20+F20 -> 18472.72 | H20: =IF(D20>0, G20/D20, 0) -> 3.9268746 | I20: =IF(D20=0, 0, IF(H20<=0, 1, IF(ABS(H20-1)<0.001, ($H$9)/($H$9+1), (1-POWER(H20,$H$9))/(1-POWER(H20,$H$9+1))))) -> 0.25251764 | J20: =MAX(0, D20 - I20*G20) -> 39.49111 | K20: =IF(C20<D$8, "ÁNO", "nie") -> ÁNO | Z20: 5
A21: Jún | B21: 30 | C21: =VLOOKUP('Správa TOB'!$I$12 & "_" & Z21, KLIMA_DB!$A$3:$I$250, 4, FALSE) -> 18.7025 | D21: =IF(C21<D$8, D$9*(D$8-C21)*B21*24/1000, 0) -> 0 | E21: =IF(C21<D$8, D$10*D$6*B21*24/1000, 0) -> 0 | F21: =IF(C21<D$8, (VLOOKUP('Správa TOB'!$I$12 & "_" & Z21, KLIMA_DB!$A$3:$I$250, 6, FALSE))*$O$30 + (VLOOKUP('Správa TOB'!$I$12 & "_" & Z21, KLIMA_DB!$A$3:$I$250, 7, FALSE))*$O$31 + (((VLOOKUP('Správa TOB'!$I$12 & "_" & Z21, KLIMA_DB!$A$3:$I$250, 8, FALSE)+VLOOKUP('Správa TOB'!$I$12 & "_" & Z21, KLIMA_DB!$A$3:$I$250, 9, FALSE))/2))*$O$32 + (((VLOOKUP('Správa TOB'!$I$12 & "_" & Z21, KLIMA_DB!$A$3:$I$250, 6, FALSE)+VLOOKUP('Správa TOB'!$I$12 & "_" & Z21, KLIMA_DB!$A$3:$I$250, 8, FALSE))/2))*$O$33 + (((VLOOKUP('Správa TOB'!$I$12 & "_" & Z21, KLIMA_DB!$A$3:$I$250, 7, FALSE)+VLOOKUP('Správa TOB'!$I$12 & "_" & Z21, KLIMA_DB!$A$3:$I$250, 8, FALSE))/2))*$O$34 + (VLOOKUP('Správa TOB'!$I$12 & "_" & Z21, KLIMA_DB!$A$3:$I$250, 5, FALSE))*$O$35, 0) -> 0 | G21: =E21+F21 -> 0 | H21: =IF(D21>0, G21/D21, 0) -> 0 | I21: =IF(D21=0, 0, IF(H21<=0, 1, IF(ABS(H21-1)<0.001, ($H$9)/($H$9+1), (1-POWER(H21,$H$9))/(1-POWER(H21,$H$9+1))))) -> 0 | J21: =MAX(0, D21 - I21*G21) -> 0 | K21: =IF(C21<D$8, "ÁNO", "nie") -> nie | Z21: 6
A22: Júl | B22: 31 | C22: =VLOOKUP('Správa TOB'!$I$12 & "_" & Z22, KLIMA_DB!$A$3:$I$250, 4, FALSE) -> 20.4025 | D22: =IF(C22<D$8, D$9*(D$8-C22)*B22*24/1000, 0) -> 0 | E22: =IF(C22<D$8, D$10*D$6*B22*24/1000, 0) -> 0 | F22: =IF(C22<D$8, (VLOOKUP('Správa TOB'!$I$12 & "_" & Z22, KLIMA_DB!$A$3:$I$250, 6, FALSE))*$O$30 + (VLOOKUP('Správa TOB'!$I$12 & "_" & Z22, KLIMA_DB!$A$3:$I$250, 7, FALSE))*$O$31 + (((VLOOKUP('Správa TOB'!$I$12 & "_" & Z22, KLIMA_DB!$A$3:$I$250, 8, FALSE)+VLOOKUP('Správa TOB'!$I$12 & "_" & Z22, KLIMA_DB!$A$3:$I$250, 9, FALSE))/2))*$O$32 + (((VLOOKUP('Správa TOB'!$I$12 & "_" & Z22, KLIMA_DB!$A$3:$I$250, 6, FALSE)+VLOOKUP('Správa TOB'!$I$12 & "_" & Z22, KLIMA_DB!$A$3:$I$250, 8, FALSE))/2))*$O$33 + (((VLOOKUP('Správa TOB'!$I$12 & "_" & Z22, KLIMA_DB!$A$3:$I$250, 7, FALSE)+VLOOKUP('Správa TOB'!$I$12 & "_" & Z22, KLIMA_DB!$A$3:$I$250, 8, FALSE))/2))*$O$34 + (VLOOKUP('Správa TOB'!$I$12 & "_" & Z22, KLIMA_DB!$A$3:$I$250, 5, FALSE))*$O$35, 0) -> 0 | G22: =E22+F22 -> 0 | H22: =IF(D22>0, G22/D22, 0) -> 0 | I22: =IF(D22=0, 0, IF(H22<=0, 1, IF(ABS(H22-1)<0.001, ($H$9)/($H$9+1), (1-POWER(H22,$H$9))/(1-POWER(H22,$H$9+1))))) -> 0 | J22: =MAX(0, D22 - I22*G22) -> 0 | K22: =IF(C22<D$8, "ÁNO", "nie") -> nie | Z22: 7
A23: Aug | B23: 31 | C23: =VLOOKUP('Správa TOB'!$I$12 & "_" & Z23, KLIMA_DB!$A$3:$I$250, 4, FALSE) -> 19.8025 | D23: =IF(C23<D$8, D$9*(D$8-C23)*B23*24/1000, 0) -> 0 | E23: =IF(C23<D$8, D$10*D$6*B23*24/1000, 0) -> 0 | F23: =IF(C23<D$8, (VLOOKUP('Správa TOB'!$I$12 & "_" & Z23, KLIMA_DB!$A$3:$I$250, 6, FALSE))*$O$30 + (VLOOKUP('Správa TOB'!$I$12 & "_" & Z23, KLIMA_DB!$A$3:$I$250, 7, FALSE))*$O$31 + (((VLOOKUP('Správa TOB'!$I$12 & "_" & Z23, KLIMA_DB!$A$3:$I$250, 8, FALSE)+VLOOKUP('Správa TOB'!$I$12 & "_" & Z23, KLIMA_DB!$A$3:$I$250, 9, FALSE))/2))*$O$32 + (((VLOOKUP('Správa TOB'!$I$12 & "_" & Z23, KLIMA_DB!$A$3:$I$250, 6, FALSE)+VLOOKUP('Správa TOB'!$I$12 & "_" & Z23, KLIMA_DB!$A$3:$I$250, 8, FALSE))/2))*$O$33 + (((VLOOKUP('Správa TOB'!$I$12 & "_" & Z23, KLIMA_DB!$A$3:$I$250, 7, FALSE)+VLOOKUP('Správa TOB'!$I$12 & "_" & Z23, KLIMA_DB!$A$3:$I$250, 8, FALSE))/2))*$O$34 + (VLOOKUP('Správa TOB'!$I$12 & "_" & Z23, KLIMA_DB!$A$3:$I$250, 5, FALSE))*$O$35, 0) -> 0 | G23: =E23+F23 -> 0 | H23: =IF(D23>0, G23/D23, 0) -> 0 | I23: =IF(D23=0, 0, IF(H23<=0, 1, IF(ABS(H23-1)<0.001, ($H$9)/($H$9+1), (1-POWER(H23,$H$9))/(1-POWER(H23,$H$9+1))))) -> 0 | J23: =MAX(0, D23 - I23*G23) -> 0 | K23: =IF(C23<D$8, "ÁNO", "nie") -> nie | Z23: 8
A24: Sep | B24: 30 | C24: =VLOOKUP('Správa TOB'!$I$12 & "_" & Z24, KLIMA_DB!$A$3:$I$250, 4, FALSE) -> 15.4355 | D24: =IF(C24<D$8, D$9*(D$8-C24)*B24*24/1000, 0) -> 4941.6629 | E24: =IF(C24<D$8, D$10*D$6*B24*24/1000, 0) -> 7469.1936 | F24: =IF(C24<D$8, (VLOOKUP('Správa TOB'!$I$12 & "_" & Z24, KLIMA_DB!$A$3:$I$250, 6, FALSE))*$O$30 + (VLOOKUP('Správa TOB'!$I$12 & "_" & Z24, KLIMA_DB!$A$3:$I$250, 7, FALSE))*$O$31 + (((VLOOKUP('Správa TOB'!$I$12 & "_" & Z24, KLIMA_DB!$A$3:$I$250, 8, FALSE)+VLOOKUP('Správa TOB'!$I$12 & "_" & Z24, KLIMA_DB!$A$3:$I$250, 9, FALSE))/2))*$O$32 + (((VLOOKUP('Správa TOB'!$I$12 & "_" & Z24, KLIMA_DB!$A$3:$I$250, 6, FALSE)+VLOOKUP('Správa TOB'!$I$12 & "_" & Z24, KLIMA_DB!$A$3:$I$250, 8, FALSE))/2))*$O$33 + (((VLOOKUP('Správa TOB'!$I$12 & "_" & Z24, KLIMA_DB!$A$3:$I$250, 7, FALSE)+VLOOKUP('Správa TOB'!$I$12 & "_" & Z24, KLIMA_DB!$A$3:$I$250, 8, FALSE))/2))*$O$34 + (VLOOKUP('Správa TOB'!$I$12 & "_" & Z24, KLIMA_DB!$A$3:$I$250, 5, FALSE))*$O$35, 0) -> 7135.1727 | G24: =E24+F24 -> 14604.366 | H24: =IF(D24>0, G24/D24, 0) -> 2.9553546 | I24: =IF(D24=0, 0, IF(H24<=0, 1, IF(ABS(H24-1)<0.001, ($H$9)/($H$9+1), (1-POWER(H24,$H$9))/(1-POWER(H24,$H$9+1))))) -> 0.33191617 | J24: =MAX(0, D24 - I24*G24) -> 94.237626 | K24: =IF(C24<D$8, "ÁNO", "nie") -> ÁNO | Z24: 9
A25: Okt | B25: 31 | C25: =VLOOKUP('Správa TOB'!$I$12 & "_" & Z25, KLIMA_DB!$A$3:$I$250, 4, FALSE) -> 10.035 | D25: =IF(C25<D$8, D$9*(D$8-C25)*B25*24/1000, 0) -> 14408.808 | E25: =IF(C25<D$8, D$10*D$6*B25*24/1000, 0) -> 7718.1667 | F25: =IF(C25<D$8, (VLOOKUP('Správa TOB'!$I$12 & "_" & Z25, KLIMA_DB!$A$3:$I$250, 6, FALSE))*$O$30 + (VLOOKUP('Správa TOB'!$I$12 & "_" & Z25, KLIMA_DB!$A$3:$I$250, 7, FALSE))*$O$31 + (((VLOOKUP('Správa TOB'!$I$12 & "_" & Z25, KLIMA_DB!$A$3:$I$250, 8, FALSE)+VLOOKUP('Správa TOB'!$I$12 & "_" & Z25, KLIMA_DB!$A$3:$I$250, 9, FALSE))/2))*$O$32 + (((VLOOKUP('Správa TOB'!$I$12 & "_" & Z25, KLIMA_DB!$A$3:$I$250, 6, FALSE)+VLOOKUP('Správa TOB'!$I$12 & "_" & Z25, KLIMA_DB!$A$3:$I$250, 8, FALSE))/2))*$O$33 + (((VLOOKUP('Správa TOB'!$I$12 & "_" & Z25, KLIMA_DB!$A$3:$I$250, 7, FALSE)+VLOOKUP('Správa TOB'!$I$12 & "_" & Z25, KLIMA_DB!$A$3:$I$250, 8, FALSE))/2))*$O$34 + (VLOOKUP('Správa TOB'!$I$12 & "_" & Z25, KLIMA_DB!$A$3:$I$250, 5, FALSE))*$O$35, 0) -> 4374.4286 | G25: =E25+F25 -> 12092.595 | H25: =IF(D25>0, G25/D25, 0) -> 0.83925023 | I25: =IF(D25=0, 0, IF(H25<=0, 1, IF(ABS(H25-1)<0.001, ($H$9)/($H$9+1), (1-POWER(H25,$H$9))/(1-POWER(H25,$H$9+1))))) -> 0.82864723 | J25: =MAX(0, D25 - I25*G25) -> 4388.3122 | K25: =IF(C25<D$8, "ÁNO", "nie") -> ÁNO | Z25: 10
A26: Nov | B26: 30 | C26: =VLOOKUP('Správa TOB'!$I$12 & "_" & Z26, KLIMA_DB!$A$3:$I$250, 4, FALSE) -> 4.5015 | D26: =IF(C26<D$8, D$9*(D$8-C26)*B26*24/1000, 0) -> 23168.056 | E26: =IF(C26<D$8, D$10*D$6*B26*24/1000, 0) -> 7469.1936 | F26: =IF(C26<D$8, (VLOOKUP('Správa TOB'!$I$12 & "_" & Z26, KLIMA_DB!$A$3:$I$250, 6, FALSE))*$O$30 + (VLOOKUP('Správa TOB'!$I$12 & "_" & Z26, KLIMA_DB!$A$3:$I$250, 7, FALSE))*$O$31 + (((VLOOKUP('Správa TOB'!$I$12 & "_" & Z26, KLIMA_DB!$A$3:$I$250, 8, FALSE)+VLOOKUP('Správa TOB'!$I$12 & "_" & Z26, KLIMA_DB!$A$3:$I$250, 9, FALSE))/2))*$O$32 + (((VLOOKUP('Správa TOB'!$I$12 & "_" & Z26, KLIMA_DB!$A$3:$I$250, 6, FALSE)+VLOOKUP('Správa TOB'!$I$12 & "_" & Z26, KLIMA_DB!$A$3:$I$250, 8, FALSE))/2))*$O$33 + (((VLOOKUP('Správa TOB'!$I$12 & "_" & Z26, KLIMA_DB!$A$3:$I$250, 7, FALSE)+VLOOKUP('Správa TOB'!$I$12 & "_" & Z26, KLIMA_DB!$A$3:$I$250, 8, FALSE))/2))*$O$34 + (VLOOKUP('Správa TOB'!$I$12 & "_" & Z26, KLIMA_DB!$A$3:$I$250, 5, FALSE))*$O$35, 0) -> 2251.2347 | G26: =E26+F26 -> 9720.4283 | H26: =IF(D26>0, G26/D26, 0) -> 0.41956167 | I26: =IF(D26=0, 0, IF(H26<=0, 1, IF(ABS(H26-1)<0.001, ($H$9)/($H$9+1), (1-POWER(H26,$H$9))/(1-POWER(H26,$H$9+1))))) -> 0.96560574 | J26: =MAX(0, D26 - I26*G26) -> 13781.955 | K26: =IF(C26<D$8, "ÁNO", "nie") -> ÁNO | Z26: 11
A27: Dec | B27: 31 | C27: =VLOOKUP('Správa TOB'!$I$12 & "_" & Z27, KLIMA_DB!$A$3:$I$250, 4, FALSE) -> -0.0985 | D27: =IF(C27<D$8, D$9*(D$8-C27)*B27*24/1000, 0) -> 31863.877 | E27: =IF(C27<D$8, D$10*D$6*B27*24/1000, 0) -> 7718.1667 | F27: =IF(C27<D$8, (VLOOKUP('Správa TOB'!$I$12 & "_" & Z27, KLIMA_DB!$A$3:$I$250, 6, FALSE))*$O$30 + (VLOOKUP('Správa TOB'!$I$12 & "_" & Z27, KLIMA_DB!$A$3:$I$250, 7, FALSE))*$O$31 + (((VLOOKUP('Správa TOB'!$I$12 & "_" & Z27, KLIMA_DB!$A$3:$I$250, 8, FALSE)+VLOOKUP('Správa TOB'!$I$12 & "_" & Z27, KLIMA_DB!$A$3:$I$250, 9, FALSE))/2))*$O$32 + (((VLOOKUP('Správa TOB'!$I$12 & "_" & Z27, KLIMA_DB!$A$3:$I$250, 6, FALSE)+VLOOKUP('Správa TOB'!$I$12 & "_" & Z27, KLIMA_DB!$A$3:$I$250, 8, FALSE))/2))*$O$33 + (((VLOOKUP('Správa TOB'!$I$12 & "_" & Z27, KLIMA_DB!$A$3:$I$250, 7, FALSE)+VLOOKUP('Správa TOB'!$I$12 & "_" & Z27, KLIMA_DB!$A$3:$I$250, 8, FALSE))/2))*$O$34 + (VLOOKUP('Správa TOB'!$I$12 & "_" & Z27, KLIMA_DB!$A$3:$I$250, 5, FALSE))*$O$35, 0) -> 1826.4924 | G27: =E27+F27 -> 9544.6592 | H27: =IF(D27>0, G27/D27, 0) -> 0.29954482 | I27: =IF(D27=0, 0, IF(H27<=0, 1, IF(ABS(H27-1)<0.001, ($H$9)/($H$9+1), (1-POWER(H27,$H$9))/(1-POWER(H27,$H$9+1))))) -> 0.98651993 | J27: =MAX(0, D27 - I27*G27) -> 22447.881 | K27: =IF(C27<D$8, "ÁNO", "nie") -> ÁNO | Z27: 12
A28: SÚČET | D28: =SUM(D16:D27) -> 176340.69 | E28: =SUM(E16:E27) -> 67969.662 | F28: =SUM(F16:F27) -> 46397.191 | G28: =SUM(G16:G27) -> 114366.85 | I28: =IF(G28>0, (I16*G16+I17*G17+I18*G18+I19*G19+I20*G20+I21*G21+I22*G22+I23*G23+I24*G24+I25*G25+I26*G26+I27*G27)/G28, 0) -> 0.71115531 | J28: =SUM(J16:J27) -> 95008.092 | O28: =SUMPRODUCT((C16:C27<D8)*B16:B27) -> 273 | P28: =IFERROR(SUMPRODUCT((C16:C27<D8)*C16:C27*B16:B27)/O28, 0) -> 6.7750934 | Q28: =SUMPRODUCT((C16:C27<D8)*(D8-C16:C27)*B16:B27) -> 3173.5995
N30: Acs Juh: | O30: =IF(AND(ISNUMBER('Správa TOB'!I75),ISNUMBER('Správa TOB'!F75),ISNUMBER('Správa TOB'!G75)),'Správa TOB'!I75*'Správa TOB'!F75*'Správa TOB'!G75*0.5,0) -> 37.01874
N31: Acs Sever: | O31: =IF(AND(ISNUMBER('Správa TOB'!I76),ISNUMBER('Správa TOB'!F76),ISNUMBER('Správa TOB'!G76)),'Správa TOB'!I76*'Správa TOB'!F76*'Správa TOB'!G76*0.5,0) -> 31.52292
N32: Acs V+Z: | O32: =IF(AND(ISNUMBER('Správa TOB'!I77),ISNUMBER('Správa TOB'!F77),ISNUMBER('Správa TOB'!G77)),'Správa TOB'!I77*'Správa TOB'!F77*'Správa TOB'!G77*0.5,0) -> 1.83315
N33: Acs JZ+JV: | O33: =IF(AND(ISNUMBER('Správa TOB'!I78),ISNUMBER('Správa TOB'!F78),ISNUMBER('Správa TOB'!G78)),'Správa TOB'!I78*'Správa TOB'!F78*'Správa TOB'!G78*0.5,0) -> 0
N34: Acs SZ+SV: | O34: =IF(AND(ISNUMBER('Správa TOB'!I79),ISNUMBER('Správa TOB'!F79),ISNUMBER('Správa TOB'!G79)),'Správa TOB'!I79*'Správa TOB'!F79*'Správa TOB'!G79*0.5,0) -> 0
N35: Acs Horiz: | O35: =IF(AND(ISNUMBER('Správa TOB'!I80),ISNUMBER('Správa TOB'!F80),ISNUMBER('Správa TOB'!G80)),'Správa TOB'!I80*'Správa TOB'!F80*'Správa TOB'!G80*0.5,0) -> 0
A39: MESAČNÝ VÝPOČET POTREBY CHLADU NA CHLADENIE
A40: Metóda: STN EN ISO 13790 - Mesačná metóda (Chladiace obdobie)
A42: VSTUPNÉ HODNOTY (CHLADENIE):
A43: Ap - Celková podlahová plocha [m²] | D43: ='Správa TOB'!I24 -> 1728.98
A44: θint,C - Požadovaná vnútorná teplota chladenia [°C] | D44: ='Správa TOB'!I106 -> 26 | G44: Tau_C (časová konštanta) [h]: | H44: =IF(D45>0, D46/(D45*3600), 0) -> 34.228057
A45: H_C - Merná tepelná strata chladenia [W/K] | D45: ='Správa TOB'!I112 -> 2315.2035 | G45: Numerický parameter a_C: | H45: =1 + H44/15 -> 3.2818705
A46: Cm - Vnútorná tepelná kapacita [J/K] | D46: =D11 -> 285281700
A48: Mesiac | B48: Dni | C48: θe [°C] | D48: Q_C,ht [kWh] | E48: Qi,C [kWh] | F48: Qs,C [kWh] | G48: Q_C,gn [kWh] | H48: γ_C [-] | I48: η_C,ls [-] | J48: Q_C,nd [kWh] | K48: Chladenie?
A49: Jan | B49: 31 | C49: =C16 -> -1.632 | D49: =MAX(0, D$45 * (D$44 - C49) * B49 * 24 / 1000) -> 47596.435 | E49: =D$10 * D$43 * B49 * 24 / 1000 -> 7718.1667 | F49: =(VLOOKUP('Správa TOB'!$I$12 & "_" & Z16, KLIMA_DB!$A$3:$I$250, 6, FALSE))*$O$30 + (VLOOKUP('Správa TOB'!$I$12 & "_" & Z16, KLIMA_DB!$A$3:$I$250, 7, FALSE))*$O$31 + (((VLOOKUP('Správa TOB'!$I$12 & "_" & Z16, KLIMA_DB!$A$3:$I$250, 8, FALSE)+VLOOKUP('Správa TOB'!$I$12 & "_" & Z16, KLIMA_DB!$A$3:$I$250, 9, FALSE))/2))*$O$32 + (((VLOOKUP('Správa TOB'!$I$12 & "_" & Z16, KLIMA_DB!$A$3:$I$250, 6, FALSE)+VLOOKUP('Správa TOB'!$I$12 & "_" & Z16, KLIMA_DB!$A$3:$I$250, 8, FALSE))/2))*$O$33 + (((VLOOKUP('Správa TOB'!$I$12 & "_" & Z16, KLIMA_DB!$A$3:$I$250, 7, FALSE)+VLOOKUP('Správa TOB'!$I$12 & "_" & Z16, KLIMA_DB!$A$3:$I$250, 8, FALSE))/2))*$O$34 + (VLOOKUP('Správa TOB'!$I$12 & "_" & Z16, KLIMA_DB!$A$3:$I$250, 5, FALSE))*$O$35 + (VLOOKUP('Správa TOB'!$I$12 & "_" & Z16, KLIMA_DB!$A$3:$I$250, 5, FALSE))*'Správa TOB'!$I$108 -> 2404.1813 | G49: =E49+F49 -> 10122.348 | H49: =IF(D49>0, G49/D49, 9999) -> 0.2126703 | I49: =IF(D49<=0, 1, IF(H49<=0, 1, IF(ABS(H49-1)<0.001, ($H$45)/($H$45+1), (1 - POWER(H49, -$H$45))/(1 - POWER(H49, -($H$45+1)))))) -> 0.21162784 | J49: =IF(C49>=13, MAX(0, G49 - I49*D49), 0) -> 0 | K49: =IF(J49>0, "ÁNO", "nie") -> nie
A50: Feb | B50: 28 | C50: =C17 -> 0.635 | D50: =MAX(0, D$45 * (D$44 - C50) * B50 * 24 / 1000) -> 39463.292 | E50: =D$10 * D$43 * B50 * 24 / 1000 -> 6971.2474 | F50: =(VLOOKUP('Správa TOB'!$I$12 & "_" & Z17, KLIMA_DB!$A$3:$I$250, 6, FALSE))*$O$30 + (VLOOKUP('Správa TOB'!$I$12 & "_" & Z17, KLIMA_DB!$A$3:$I$250, 7, FALSE))*$O$31 + (((VLOOKUP('Správa TOB'!$I$12 & "_" & Z17, KLIMA_DB!$A$3:$I$250, 8, FALSE)+VLOOKUP('Správa TOB'!$I$12 & "_" & Z17, KLIMA_DB!$A$3:$I$250, 9, FALSE))/2))*$O$32 + (((VLOOKUP('Správa TOB'!$I$12 & "_" & Z17, KLIMA_DB!$A$3:$I$250, 6, FALSE)+VLOOKUP('Správa TOB'!$I$12 & "_" & Z17, KLIMA_DB!$A$3:$I$250, 8, FALSE))/2))*$O$33 + (((VLOOKUP('Správa TOB'!$I$12 & "_" & Z17, KLIMA_DB!$A$3:$I$250, 7, FALSE)+VLOOKUP('Správa TOB'!$I$12 & "_" & Z17, KLIMA_DB!$A$3:$I$250, 8, FALSE))/2))*$O$34 + (VLOOKUP('Správa TOB'!$I$12 & "_" & Z17, KLIMA_DB!$A$3:$I$250, 5, FALSE))*$O$35 + (VLOOKUP('Správa TOB'!$I$12 & "_" & Z17, KLIMA_DB!$A$3:$I$250, 5, FALSE))*'Správa TOB'!$I$108 -> 4044.7908 | G50: =E50+F50 -> 11016.038 | H50: =IF(D50>0, G50/D50, 9999) -> 0.27914646 | I50: =IF(D50<=0, 1, IF(H50<=0, 1, IF(ABS(H50-1)<0.001, ($H$45)/($H$45+1), (1 - POWER(H50, -$H$45))/(1 - POWER(H50, -($H$45+1)))))) -> 0.27607874 | J50: =IF(C50>=13, MAX(0, G50 - I50*D50), 0) -> 0 | K50: =IF(J50>0, "ÁNO", "nie") -> nie
A51: Mar | B51: 31 | C51: =C18 -> 5.402 | D51: =MAX(0, D$45 * (D$44 - C51) * B51 * 24 / 1000) -> 35480.29 | E51: =D$10 * D$43 * B51 * 24 / 1000 -> 7718.1667 | F51: =(VLOOKUP('Správa TOB'!$I$12 & "_" & Z18, KLIMA_DB!$A$3:$I$250, 6, FALSE))*$O$30 + (VLOOKUP('Správa TOB'!$I$12 & "_" & Z18, KLIMA_DB!$A$3:$I$250, 7, FALSE))*$O$31 + (((VLOOKUP('Správa TOB'!$I$12 & "_" & Z18, KLIMA_DB!$A$3:$I$250, 8, FALSE)+VLOOKUP('Správa TOB'!$I$12 & "_" & Z18, KLIMA_DB!$A$3:$I$250, 9, FALSE))/2))*$O$32 + (((VLOOKUP('Správa TOB'!$I$12 & "_" & Z18, KLIMA_DB!$A$3:$I$250, 6, FALSE)+VLOOKUP('Správa TOB'!$I$12 & "_" & Z18, KLIMA_DB!$A$3:$I$250, 8, FALSE))/2))*$O$33 + (((VLOOKUP('Správa TOB'!$I$12 & "_" & Z18, KLIMA_DB!$A$3:$I$250, 7, FALSE)+VLOOKUP('Správa TOB'!$I$12 & "_" & Z18, KLIMA_DB!$A$3:$I$250, 8, FALSE))/2))*$O$34 + (VLOOKUP('Správa TOB'!$I$12 & "_" & Z18, KLIMA_DB!$A$3:$I$250, 5, FALSE))*$O$35 + (VLOOKUP('Správa TOB'!$I$12 & "_" & Z18, KLIMA_DB!$A$3:$I$250, 5, FALSE))*'Správa TOB'!$I$108 -> 6760.3428 | G51: =E51+F51 -> 14478.51 | H51: =IF(D51>0, G51/D51, 9999) -> 0.40807191 | I51: =IF(D51<=0, 1, IF(H51<=0, 1, IF(ABS(H51-1)<0.001, ($H$45)/($H$45+1), (1 - POWER(H51, -$H$45))/(1 - POWER(H51, -($H$45+1)))))) -> 0.39504173 | J51: =IF(C51>=13, MAX(0, G51 - I51*D51), 0) -> 0 | K51: =IF(J51>0, "ÁNO", "nie") -> nie
...

Sheet Vizualizácia výsledkov
A1: ENERGETICKÁ BILANCIA A NÁVRHOVÉ PARAMETRE ZDROJOV TEPLA A CHLADU
A2: Podľa STN EN ISO 13790, STN 73 0540 a STN EN 12831 (Mesačná metóda a dimenzovanie HVAC)
A4: UKAZOVATEĽ BUDOVY | B4: HODNOTA | C4: JEDNOTKA | D4: POPIS / NORMA
A5: Lokalita budovy | B5: ='Správa TOB'!I12 -> Bratislava-letisko | C5: - | D5: Vybraná klimatická oblasť SR
A6: Celková podlahová plocha (Ap) | B6: ='Správa TOB'!I24 -> 1728.98 | C6: m² | D6: Vykurovaná a chladená plocha budovy
A7: Obostavaný objem (V) | B7: ='Správa TOB'!I23 -> 5273.389 | C7: m³ | D7: Geometrický objem budovy
A8: Faktor tvaru budovy (A/V) | B8: ='Správa TOB'!I27 -> 0.56072101 | C8: 1/m | D8: Kompaktnosť tvaru budovy
A9: Celková merná strata (H) | B9: ='Správa TOB'!I112 -> 2315.2035 | C9: W/K | D9: Straty prechodom tepla + vetraním
A10: Počet dennostupňov (D) | B10: ='Správa TOB'!I29 -> 3173.5995 | C10: K·deň | D10: Vykurovacie obdobie
A11: Potreba tepla na vykurovanie (Q_H,nd) | B11: =Výpočet_mesacny!J28 -> 95008.092 | C11: kWh/a | D11: Ročná energetická potreba tepla
A12: Merná potreba tepla (q_H) | B12: ='Správa TOB'!I114 -> 54.950371 | C12: kWh/(m²·a) | D12: Merný ukazovateľ vykurovania
A13: Potreba chladu na chladenie (Q_C,nd) | B13: =Výpočet_mesacny!J61 -> 39921.333 | C13: kWh/a | D13: Ročná energetická potreba chladu
A14: Merná potreba chladu (q_C) | B14: ='Správa TOB'!I115 -> 90.865789 | C14: kWh/(m²·a) | D14: Merný ukazovateľ chladenia
A17: 1. NÁVRHOVÉ PARAMETRE PRE ZDROJ TEPLA (VYKUROVANIE)
A18: Parameter pre dimenzovanie | B18: Hodnota | C18: Jedn. | D18: Fyzikálny význam / Zdroj vzorca
A19: Výpočtová vonkajšia teplota v zime (θe) | B19: =IFERROR(VLOOKUP('Správa TOB'!$I$12,KLIMA_DB!$P$3:$R$15,3,FALSE),-11) -> -11 | C19: °C | D19: Normatívna teplota najchladnejšieho dňa (STN 73 0540-3)
A20: Výpočtová vnútorná teplota vykurovania (θi) | B20: ='Správa TOB'!$I$92 -> 20 | C20: °C | D20: Požadovaná vnútorná teplota priestorov
A21: Návrhový teplotný rozdiel (Δθ_H = θi - θe) | B21: =B20-B19 -> 31 | C21: K | D21: Teplotný spád pre dimenzovanie vykurovacieho výkonu
A22: Merná tepelná strata prechodom tepla (Ht) | B22: ='Správa TOB'!$I$85 -> 1598.0226 | C22: W/K | D22: Tepelná priepustnosť obvodových konštrukcií
A23: Merná tepelná strata vetraním (Hv) | B23: ='Správa TOB'!$I$86 -> 717.1809 | C23: W/K | D23: Tepelná priepustnosť výmenou vzduchu
A24: Celková merná tepelná strata (H = Ht + Hv) | B24: ='Správa TOB'!$I$112 -> 2315.2035 | C24: W/K | D24: Celková merná strata budovy
A25: Návrhová strata prechodom tepla (Φ_T) | B25: =B22*B21/1000 -> 49.5387 | C25: kW | D25: Výkon potrebný na krytie strát konštrukciami
A26: Návrhová strata vetraním (Φ_V) | B26: =B23*B21/1000 -> 22.232608 | C26: kW | D26: Výkon potrebný na krytie strát vetraním
A27: 🔥 NÁVRHOVÝ TEPELNÝ VÝKON ZDROJA TEPLA (Φ_HL) | B27: =B24*B21/1000 -> 71.771308 | C27: kW | D27: Celkový inštalovaný výkon kotla / tepelného čerpadla
A28: Merný inštalovaný výkon vykurovania (p_H) | B28: =IF(B6>0, B27*1000/B6, 0) -> 41.51078 | C28: W/m² | D28: Špecifický výkon na jednotku podlahovej plochy
A29: Ekvivalentný čas plnej prevádzky zdroja (t_eq,H) | B29: =IF(B27>0, B11/B27, 0) -> 1323.7615 | C29: h/a | D29: Počet plných prevádzkových hodín zdroja tepla ročne
A32: 2. NÁVRHOVÉ PARAMETRE PRE ZDROJ CHLADU (CHLADENIE)
A33: Parameter pre dimenzovanie | B33: Hodnota | C33: Jedn. | D33: Fyzikálny význam / Zdroj vzorca
A34: Výpočtová vonkajšia teplota v lete (θe,C) | B34: ='Správa TOB'!$I$105 -> 33 | C34: °C | D34: Letná návrhová vonkajšia teplota (STN 73 0540-3)
A35: Požadovaná vnútorná teplota chladenia (θint,C) | B35: ='Správa TOB'!$I$106 -> 26 | C35: °C | D35: Požadovaná vnútorná teplota pri chladení
A36: Návrhový teplotný rozdiel (Δθ_C = θe,C - θint,C) | B36: =MAX(0, B34-B35) -> 7 | C36: K | D36: Kladný teplotný spád prenikajúci do budovy
A37: Tepelná záťaž obálkou a vetraním (Φ_env,C) | B37: =B24*B36/1000 -> 16.206424 | C37: kW | D37: Tepelný príkon prenikajúci cez steny, strechu a vetranie
A38: Špičková solárna tepelná záťaž (Φ_sol,C) | B38: =(SUMPRODUCT('Správa TOB'!$J$75:$J$80)*2 + 'Správa TOB'!$I$108)*0.65 -> 98.948462 | C38: kW | D38: Okamžitý špičkový solárny príkon cez okná a strechu
A39: Vnútorná tepelná záťaž (Φ_int,C) | B39: ='Správa TOB'!$I$68*B6/1000 -> 10.37388 | C39: kW | D39: Tepelný zisk od osôb, osvetlenia a technológií
A40: ❄️ NÁVRHOVÝ CHLADIACI VÝKON ZDROJA CHLADU (Φ_CL) | B40: =B37+B38+B39 -> 125.52877 | C40: kW | D40: Celkový inštalovaný chladiaci výkon chilleru / VRF / TČ
A41: Merný inštalovaný výkon chladenia (p_C) | B41: =IF(B6>0, B40*1000/B6, 0) -> 72.602787 | C41: W/m² | D41: Špecifický chladiaci výkon na m² podlahovej plochy
A42: Ekvivalentný čas plnej prevádzky chladenia (t_eq,C) | B42: =IF(B40>0, B13/B40, 0) -> 318.02537 | C42: h/a | D42: Počet plných prevádzkových hodín chladiaceho zdroja
A45: MESAČNÝ PREHĽAD ENERGETICKEJ BILANCIE
A46: Mesiac | B46: Straty Q_loss [kWh] | C46: Zisky Q_gain [kWh] | D46: Vykurovanie Q_H,nd [kWh] | E46: Chladenie Q_C,nd [kWh]
A47: Jan | B47: =Výpočet_mesacny!D16 -> 34505.348 | C47: =Výpočet_mesacny!G16 -> 9812.4209 | D47: =Výpočet_mesacny!J16 -> 24806.742 | E47: =Výpočet_mesacny!J49 -> 0
...
